Workbook

Sheet Instructions & Scoring Guide
B2: FALCON FREIGHT SOLUTIONS
B3: Third-Party & Vendor Risk Questionnaire
B4: Information Security, Data Privacy & Business Continuity Due Diligence Instrument
B5: CONFIDENTIAL – FOR COMPLETION BY THE NAMED THIRD PARTY / VENDOR
B7: Issued By | C7: Falcon Freight Solutions – Group Risk & Compliance
B8: Document Owner | C8: Director of IT & Security (CISO-equivalent)
B9: Version | C9: 1.0
B10: Issue Date | C10: 30 July 2026
B11: Response Due | C11: Within 15 business days of receipt
B12: Applies To | C12: All third parties and vendors with access to Falcon Freight Solutions data, systems, or facilities
B14: How to Use This Questionnaire
B15: 1. Complete the Vendor Profile fields at the top of the 'Questionnaire' tab (legal name, contact, services provided, data handled).
B16: 2. Answer every question using the dropdown in the Response column: Yes / Partial / Compensating Control / No / Not Applicable.
B17: 3. Where you answer 'Partial' or 'No', explain the gap and any compensating control in the Comments column.
B18: 4. Attach or reference supporting evidence (policy, certificate, audit report) in the Evidence Reference column.
B19: 5. Return the completed workbook to your Falcon Freight Solutions relationship owner. Do not alter section headers, question text, or formulas.
B20: 6. Falcon Freight Solutions' Risk & Compliance team will review responses and populate the 'Scoring Summary' tab automatically from your answers.
B22: Contents
B23: 1. Instructions & Scoring Guide – how responses are scored and rated
B24: 2. Vendor Directory – Falcon Freight Solutions' registered third parties and questionnaire tracking status
B25: 3. Questionnaire – vendor profile plus 76 questions across 12 risk domains
B26: 4. Scoring Summary – auto-calculated section and overall risk rating once completed
... B30: Each question is answered Yes / Partial / Compensating Control / No / Not Applicable. Responses are converted to points, rolled up into a Section Score (%), then combined into a single weighted Overall Vendor Risk Score (%) using the section weights on the 'Weighting & Vendor Focus Areas' tab. The overall score maps to a risk rating consistent with Falcon Freight Solutions' Enterprise Risk Register rating bands (Low/Medium/High/Critical).
B32: Response Option | C32: Interpretation / Required Action
B33: Yes (2 pts) | C33: Control is fully implemented and operating effectively. Approve. Standard annual re-assessment cadence.
B34: Partial / Compensating Control (1 pt) | C34: Control is partially implemented, or an alternative compensating control is in place. Approve with monitoring. Remediation plan for gaps within 90 days; re-assess in 6 months.
B35: No (0 pts) | C35: Control is not implemented. Requires a remediation plan and timeline. Conditional approval. Mandatory remediation plan within 30 days, escalate to Risk & Compliance Committee.
B36: Not Applicable (excluded) | C36: Question does not apply to the services provided; excluded from scoring denominator.
B38: Weighted Score | C38: Overall Risk Rating
B39: 85% - 100% | C39: Low Risk
B40: 70% - 84% | C40: Medium Risk
B41: 50% - 69% | C41: High Risk
B42: Below 50% | C42: Critical Risk
B44: Note: Sections 2 (Data Privacy), 5 (Data Protection & Cryptography), and 10 (Incident Management) carry the highest weighting (15%, 12%, 12% respectively) reflecting Falcon Freight Solutions' exposure to customer PII, cross-border data transfer obligations under GDPR and South Africa's POPIA, and the criticality of timely breach notification. See the 'Weighting & Vendor Focus Areas' tab for the full weighting table and which domains are the priority focus for each known Falcon Freight Solutions vendor.

Sheet Vendor Directory
A1: THIRD-PARTY VENDOR DIRECTORY & QUESTIONNAIRE TRACKER
A2: Registered third parties linked to Falcon Freight Solutions (source: Enterprise Risk Register – Third-Party Vendor Register)
A4: Vendor ID | B4: Vendor Name | C4: Vendor Type | D4: Services Provided | E4: Data Types Handled | F4: Inherent Risk Level | G4: Risk Owner | H4: Last Assessment | I4: Next Assessment | J4: Questionnaire Status | K4: Date Issued | L4: Date Returned | M4: Overall Score (%) | N4: Rating
A5: TPV-001 | B5: Microsoft Azure | C5: Cloud / SaaS Vendor | D5: Hosting of cloud-based shipment tracking platform & related infrastructure | E5: Shipment records; customer PII; geolocation data; system logs | F5: High | G5: Cloud Security Architect | H5: 20-Jan-2026 | I5: 20-Jan-2027 | J5: Received – Reviewed | K5: 30-Jul-2026 | L5: 12-Aug-2026 | M5: 89.2 | N5: Low Risk
A6: TPV-002 | B6: SAP Logistics | C6: ERP / Warehouse Software Vendor | D6: Warehouse management and inventory control software platform | E6: Inventory logs; shipment manifests; supplier records | F6: Medium | G6: Director of IT & Security | H6: 05-Apr-2026 | I6: 05-Apr-2027 | J6: Not Sent
A7: TPV-003 | B7: DHL Partner Services | C7: Delivery / Logistics Subcontractor | D7: Last-mile package delivery and driver tracking services | E7: Customer names; delivery addresses; phone numbers; geolocation logs | F7: High | G7: VP of Supply Chain & Logistics | H7: 10-May-2026 | I7: 10-May-2027 | J7: Not Sent
A8: TPV-004 | B8: PayFast Payment Gateway | C8: Payment Processing Provider | D8: Online payment processing for freight and customs invoicing | E8: Payment card data; transaction records; billing PII | F8: High | G8: Head of Legal & Compliance | H8: 15-Feb-2026 | I8: 15-Feb-2027 | J8: Not Sent
A9: TPV-005 | B9: SecureNet IT Services | C9: Managed IT / Security Services Provider | D9: Outsourced network monitoring, helpdesk, and security operations support | E9: System credentials; network configuration data; access logs | F9: Medium | G9: Director of IT & Security | H9: 12-Sep-2025 | I9: 12-Sep-2026 | J9: Not Sent
A11: Instructions: issue a copy of the 'Questionnaire' tab to each vendor below. When a response is returned, transfer the vendor's answers into a dedicated copy of this workbook, record the resulting Overall Score and Rating from the 'Scoring Summary' tab into columns M–N above, and update Questionnaire Status accordingly.

Sheet Questionnaire
A1: FALCON FREIGHT SOLUTIONS – THIRD-PARTY & VENDOR RISK QUESTIONNAIRE
A3: SECTION 0 – VENDOR & ENGAGEMENT PROFILE (to be completed by the vendor)
A4: Vendor Legal Name | B4: Microsoft Ireland Operations Limited, trading as Microsoft Azure
A5: Registered Address / HQ Location | B5: Global HQ: One Microsoft Way, Redmond, Washington, USA. EMEA/Africa operations: One Microsoft Place, Dublin, Ireland
A6: Primary Contact (Name, Title, Email, Phone) | B6: Thandiwe Mokoena, Enterprise Account Manager – Azure Africa, [email protected], +27 11 245 0000
A7: Vendor Type (Delivery Fleet / Brokerage / SaaS-Cloud / Integration Partner / Facility-Warehousing / Other) | B7: SaaS-Cloud
A8: Services Provided to Falcon Freight Solutions | B8: Hosting of Falcon Freight Solutions' cloud-based shipment tracking platform, including compute, storage, networking and platform security services
A9: Data Types Handled on Falcon Freight Solutions' Behalf | B9: Shipment records; customer PII; geolocation data; system/application logs
A10: Data Residency / Hosting Location(s) | B10: Primary: Azure South Africa North (Johannesburg); Secondary/DR: Azure West Europe (Netherlands)
A11: Years Providing This Service to Falcon Freight Solutions | B11: 4 years
A12: Number of Personnel with Access to Falcon Freight Solutions Data/Systems | B12: No standing Microsoft personnel access to customer data; access is limited to just-in-time, customer-approved sessions (Customer Lockbox) for support purposes only
A13: Do You Use Subcontractors / Fourth Parties for This Engagement? (Y/N – detail if yes) | B13: Yes – Microsoft uses a global network of subprocessors for datacenter operations and support services, disclosed via the Microsoft Online Services Subprocessor List
A14: Applicable Regulatory Frameworks (GDPR, POPIA – South Africa, other) | B14: GDPR, POPIA (South Africa), ISO/IEC 27701, PCI DSS
A15: Relevant Certifications Held (ISO 27001, SOC 2 Type II, PCI DSS, other) | B15: ISO/IEC 27001:2022, ISO/IEC 27017, ISO/IEC 27018, SOC 2 Type II, PCI DSS Level 1 Service Provider
A16: Questionnaire Completed By (Name, Title, Date) | B16: Priya Naidoo, Enterprise Compliance Manager, Azure Compliance Team, 12 August 2026
A18: Q# | B18: Question | C18: Response | D18: Points | E18: Evidence Reference | F18: Comments / Compensating Control
A20: S1 – Corporate Governance & Certifications (Weight: 5%)
A21: 1.1 | B21: Does your organization maintain a formally documented Information Security Policy approved by senior management? | C21: Yes | D21: =IF(C21="","",IF(C21="Not Applicable","N/A",IF(C21="Yes",2,IF(OR(C21="Partial",C21="Compensating Control"),1,0)))) -> 2 | E21: Microsoft Information Security Policy summary – Service Trust Portal
A22: 1.2 | B22: Do you hold a current ISO/IEC 27001 certification or equivalent (attach certificate / scope statement)? | C22: Yes | D22: =IF(C22="","",IF(C22="Not Applicable","N/A",IF(C22="Yes",2,IF(OR(C22="Partial",C22="Compensating Control"),1,0)))) -> 2 | E22: ISO/IEC 27001:2022 certificate & Statement of Applicability – Service Trust Portal
A23: 1.3 | B23: Do you undergo an annual independent security audit (e.g., SOC 2 Type II, penetration test)? | C23: Yes | D23: =IF(C23="","",IF(C23="Not Applicable","N/A",IF(C23="Yes",2,IF(OR(C23="Partial",C23="Compensating Control"),1,0)))) -> 2 | E23: SOC 2 Type II report (semi-annual) – Service Trust Portal, NDA required
A24: 1.4 | B24: Is there a named executive or individual accountable for information security (CISO or equivalent)? | C24: Yes | D24: =IF(C24="","",IF(C24="Not Applicable","N/A",IF(C24="Yes",2,IF(OR(C24="Partial",C24="Compensating Control"),1,0)))) -> 2 | E24: Microsoft CISO organization chart – Service Trust Portal
A25: 1.5 | B25: Do you maintain cyber liability / errors & omissions insurance covering data breach events? | C25: Yes | D25: =IF(C25="","",IF(C25="Not Applicable","N/A",IF(C25="Yes",2,IF(OR(C25="Partial",C25="Compensating Control"),1,0)))) -> 2 | E25: Certificate of cyber/E&O insurance available on request
A26: Section Score – Corporate Governance & Certifications | D26: =IFERROR(SUM(D21:D25)/(2*COUNT(D21:D25)),"") -> 1
A28: S2 – Data Privacy & Regulatory Compliance (Weight: 15%)
A29: 2.1 | B29: Do you process personal data on behalf of Falcon Freight Solutions (customer, employee, or driver data)? | C29: Yes | D29: =IF(C29="","",IF(C29="Not Applicable","N/A",IF(C29="Yes",2,IF(OR(C29="Partial",C29="Compensating Control"),1,0)))) -> 2 | E29: Microsoft Online Services Terms – Data Processing Addendum
A30: 2.2 | B30: Have you conducted a Data Protection Impact Assessment (DPIA) for the services provided to Falcon Freight Solutions? | C30: Partial | D30: =IF(C30="","",IF(C30="Not Applicable","N/A",IF(C30="Yes",2,IF(OR(C30="Partial",C30="Compensating Control"),1,0)))) -> 1 | E30: Microsoft DPIA support documentation – Service Trust Portal | F30: Microsoft provides tooling, documentation and audit reports to support customer DPIAs; a bespoke DPIA for the FFS tracking-platform deployment has not been separately produced. Recommend FFS's own DPIA is completed using Microsoft's supporting evidence.
A31: 2.3 | B31: Do you have a documented lawful basis and a signed Data Processing Agreement (DPA) in place with Falcon Freight Solutions? | C31: Yes | D31: =IF(C31="","",IF(C31="Not Applicable","N/A",IF(C31="Yes",2,IF(OR(C31="Partial",C31="Compensating Control"),1,0)))) -> 2 | E31: Microsoft Product Terms – Online Services DPA (signed as part of Enterprise Agreement)
A32: 2.4 | B32: Are cross-border data transfers governed by Standard Contractual Clauses or an equivalent transfer mechanism? | C32: Yes | D32: =IF(C32="","",IF(C32="Not Applicable","N/A",IF(C32="Yes",2,IF(OR(C32="Partial",C32="Compensating Control"),1,0)))) -> 2 | E32: EU Standard Contractual Clauses incorporated in Microsoft Product Terms
A33: 2.5 | B33: Do you comply with the Protection of Personal Information Act (POPIA, South Africa) and/or GDPR, as applicable to your operations? | C33: Yes | D33: =IF(C33="","",IF(C33="Not Applicable","N/A",IF(C33="Yes",2,IF(OR(C33="Partial",C33="Compensating Control"),1,0)))) -> 2 | E33: POPIA/GDPR compliance statements – Microsoft Trust Center
A34: 2.6 | B34: Do you have a documented data retention and secure deletion schedule for Falcon Freight Solutions data? | C34: Partial | D34: =IF(C34="","",IF(C34="Not Applicable","N/A",IF(C34="Yes",2,IF(OR(C34="Partial",C34="Compensating Control"),1,0)))) -> 1 | E34: Azure Data Retention/Lifecycle Management documentation | F34: Retention and secure-deletion capability is provided (e.g. Storage lifecycle policies), but the retention schedule itself is configured and owned by Falcon Freight Solutions, not Microsoft.
A35: 2.7 | B35: Can you support Falcon Freight Solutions' obligations to fulfil data subject access, correction, and deletion requests within statutory timeframes? | C35: Yes | D35: =IF(C35="","",IF(C35="Not Applicable","N/A",IF(C35="Yes",2,IF(OR(C35="Partial",C35="Compensating Control"),1,0)))) -> 2 | E35: Microsoft Data Subject Request (DSR) portal and guidance documentation
A36: 2.8 | B36: Do you notify Falcon Freight Solutions of any regulatory inquiry or investigation involving data processed on its behalf? | C36: Yes | D36: =IF(C36="","",IF(C36="Not Applicable","N/A",IF(C36="Yes",2,IF(OR(C36="Partial",C36="Compensating Control"),1,0)))) -> 2 | E36: Data Processing Addendum – regulatory inquiry notification clause
A37: Section Score – Data Privacy & Regulatory Compliance | D37: =IFERROR(SUM(D29:D36)/(2*COUNT(D29:D36)),"") -> 0.875
A39: S3 – Information Security Policy & Governance (Weight: 5%)
A40: 3.1 | B40: Are information security roles and responsibilities formally defined and communicated? | C40: Yes | D40: =IF(C40="","",IF(C40="Not Applicable","N/A",IF(C40="Yes",2,IF(OR(C40="Partial",C40="Compensating Control"),1,0)))) -> 2 | E40: Microsoft security organization structure – Service Trust Portal
A41: 3.2 | B41: Do all personnel with access to Falcon Freight Solutions data undergo background verification checks prior to hire? | C41: Yes | D41: =IF(C41="","",IF(C41="Not Applicable","N/A",IF(C41="Yes",2,IF(OR(C41="Partial",C41="Compensating Control"),1,0)))) -> 2 | E41: Microsoft HR background screening policy summary
A42: 3.3 | B42: Do personnel receive mandatory security awareness training, including phishing simulation, at least annually? | C42: Yes | D42: =IF(C42="","",IF(C42="Not Applicable","N/A",IF(C42="Yes",2,IF(OR(C42="Partial",C42="Compensating Control"),1,0)))) -> 2 | E42: Microsoft mandatory security training completion records (attestation)
A43: 3.4 | B43: Do personnel sign confidentiality / non-disclosure agreements covering Falcon Freight Solutions data? | C43: Yes | D43: =IF(C43="","",IF(C43="Not Applicable","N/A",IF(C43="Yes",2,IF(OR(C43="Partial",C43="Compensating Control"),1,0)))) -> 2 | E43: Standard Microsoft employment confidentiality terms
A44: 3.5 | B44: Is there a formal disciplinary process for information security policy violations? | C44: Yes | D44: =IF(C44="","",IF(C44="Not Applicable","N/A",IF(C44="Yes",2,IF(OR(C44="Partial",C44="Compensating Control"),1,0)))) -> 2 | E44: Microsoft Standards of Business Conduct / disciplinary policy
A45: 3.6 | B45: Are security responsibilities that survive termination of employment defined and enforced? | C45: Yes | D45: =IF(C45="","",IF(C45="Not Applicable","N/A",IF(C45="Yes",2,IF(OR(C45="Partial",C45="Compensating Control"),1,0)))) -> 2 | E45: Microsoft HR offboarding and post-termination security policy
...

Sheet Scoring Summary
A1: VENDOR RISK SCORING SUMMARY
A2: Auto-calculated from responses entered on the 'Questionnaire' tab
A4: Risk Domain | B4: Weight | C4: Section Score | D4: Weighted Contribution
A5: S1 – Corporate Governance & Certifications | B5: 0.05 | C5: =Questionnaire!D26 -> 1 | D5: =IFERROR(C5*B5,0) -> 0.05
A6: S2 – Data Privacy & Regulatory Compliance | B6: 0.15 | C6: =Questionnaire!D37 -> 0.875 | D6: =IFERROR(C6*B6,0) -> 0.13125
A7: S3 – Information Security Policy & Governance | B7: 0.05 | C7: =Questionnaire!D46 -> 1 | D7: =IFERROR(C7*B7,0) -> 0.05
A8: S4 – Access Control & Identity Management | B8: 0.1 | C8: =Questionnaire!D56 -> 0.85714286 | D8: =IFERROR(C8*B8,0) -> 0.085714286
A9: S5 – Data Protection & Cryptography | B9: 0.12 | C9: =Questionnaire!D66 -> 0.83333333 | D9: =IFERROR(C9*B9,0) -> 0.1
A10: S6 – Network & Application / API Security | B10: 0.1 | C10: =Questionnaire!D76 -> 0.92857143 | D10: =IFERROR(C10*B10,0) -> 0.092857143
A11: S7 – Endpoint, Cloud & Infrastructure Security | B11: 0.08 | C11: =Questionnaire!D86 -> 1 | D11: =IFERROR(C11*B11,0) -> 0.08
A12: S8 – Physical & Environmental Security | B12: 0.06 | C12: =Questionnaire!D95 -> 1 | D12: =IFERROR(C12*B12,0) -> 0.06
A13: S9 – Business Continuity & Disaster Recovery | B13: 0.07 | C13: =Questionnaire!D104 -> 0.83333333 | D13: =IFERROR(C13*B13,0) -> 0.058333333
A14: S10 – Incident Management & Breach Notification | B14: 0.12 | C14: =Questionnaire!D114 -> 0.78571429 | D14: =IFERROR(C14*B14,0) -> 0.094285714
A15: S11 – Subcontractor / Fourth-Party Risk Management | B15: 0.06 | C15: =Questionnaire!D122 -> 0.9 | D15: =IFERROR(C15*B15,0) -> 0.054
A16: S12 – Right to Audit, Insurance & Compliance Monitoring | B16: 0.04 | C16: =Questionnaire!D130 -> 0.9 | D16: =IFERROR(C16*B16,0) -> 0.036
A17: OVERALL VENDOR RISK SCORE | B17: =SUM(B5:B16) -> 1 | D17: =SUM(D5:D16) -> 0.89244048
A19: =CONCATENATE("Questions answered: ",COUNTA(Questionnaire!C19:C130)," of 76") -> Questions answered: 76 of 76
A21: OVERALL RISK RATING | C21: =IF(COUNTA(Questionnaire!C19:C130)<76,"Incomplete",IF(D17>=0.85,"Low Risk",IF(D17>=0.7,"Medium Risk",IF(D17>=0.5,"High Risk","Critical Risk")))) -> Low Risk
A46: Scores will read blank/0% until the vendor's responses are entered on the 'Questionnaire' tab. This tab recalculates automatically as responses are completed.

Sheet Weighting & Vendor Focus Areas
A1: SECTION WEIGHTING
A3: Risk Domain | B3: Weight
A4: S1 – Corporate Governance & Certifications | B4: 0.05
A5: S2 – Data Privacy & Regulatory Compliance | B5: 0.15
A6: S3 – Information Security Policy & Governance | B6: 0.05
A7: S4 – Access Control & Identity Management | B7: 0.1
A8: S5 – Data Protection & Cryptography | B8: 0.12
A9: S6 – Network & Application / API Security | B9: 0.1
A10: S7 – Endpoint, Cloud & Infrastructure Security | B10: 0.08
A11: S8 – Physical & Environmental Security | B11: 0.06
A12: S9 – Business Continuity & Disaster Recovery | B12: 0.07
A13: S10 – Incident Management & Breach Notification | B13: 0.12
A14: S11 – Subcontractor / Fourth-Party Risk Management | B14: 0.06
A15: S12 – Right to Audit, Insurance & Compliance Monitoring | B15: 0.04
A16: TOTAL | B16: =SUM(B4:B15) -> 1
A19: VENDOR-SPECIFIC PRIORITY FOCUS AREAS
A20: Guidance for Falcon Freight Solutions reviewers on which questionnaire sections warrant the closest scrutiny per known vendor, based on the Enterprise Risk Register.
A22: Vendor | B22: Priority Sections | C22: Rationale
A23: TPV-001 – Microsoft Azure | B23: S4, S5, S6, S7, S9 | C23: Cloud host of the shipment tracking platform and core infrastructure; IAM least-privilege, encryption, API security, and SOC 2 coverage are priority controls (RSK-006, RSK-010).
A24: TPV-002 – SAP Logistics | B24: S1, S4, S6, S9 | C24: Warehouse management and inventory software vendor; patch management, access control, and continuity of the on-premise warehouse system are priority controls (RSK-003, RSK-005).
A25: TPV-003 – DHL Partner Services | B25: S2, S4, S5, S10, S11 | C25: Highest-touch PII exposure (customer names, addresses, phone numbers, live geolocation) via the last-mile delivery app; data masking and screenshot-blocking are critical controls (RSK-002, RSK-008).
A26: TPV-004 – PayFast Payment Gateway | B26: S2, S5, S6, S12 | C26: Processes payment card data and billing PII for freight and customs invoicing; encryption, tokenization, PCI-DSS compliance, and audit rights are priority controls (RSK-001).
A27: TPV-005 – SecureNet IT Services | B27: S3, S4, S7, S10 | C27: Manages network monitoring and security operations with privileged access to Falcon Freight Solutions systems; access control, endpoint/SIEM monitoring, and incident response coordination are priority controls (RSK-004, RSK-011).
