Workbook

Sheet Instructions for Use
B2: ISO/IEC 27001:2022 Gap analysis questionnaire - Instructions for use - Falcon Freight Solutions
B4: This questionnaire provides a structured framework for systematically evaluating an organization's information security management practices against ISO/IEC 27001:2022. While it can be used for self-assessment, it is primarily designed to support a gap analysis facilitated by an experienced ISO27k consultant or auditor offering guidance, clarification and a more objective assessment. The questionnaire has two parts: Part 1 - ISO/IEC 27001:2022 Clauses (28 questions) - covers the ISO/IEC 27001:2022 main body clauses 4 to 10. Conformity with the requirements in these clauses is mandatory for all certified organizations. Part 2 - ISO/IEC 27001:2022 Annex A information security controls (133 questions) - covers the ISO/IEC 27001:2022 Annex A controls. Conformity with the requirements in the Annex is discretionary: it is only required if the organization determines that the controls are applicable, meaming that they are required to mitigate the associated information risks. Understanding the questions To better understand the requirements behind each question: Part 1 - ISO/IEC 27001:2022 Clauses - Please study ISO/IEC 27001:2022 Clauses 4 to 10. Part 2 - ISO/IEC 27001:2022 Annex A Controls - Please study the 'Guidance' paragraphs for each control in ISO/IEC 27002:2022. ISO/IEC 27002 provides about a page of explanation for each control, expanding on the control names given in ISO/IEC 27001 Annex A. Answering questions When answering, please use the dropdown box to select your response. In the 'Policy' or 'other document(s)' cells, please provide details of any documentation supporting your response, along with the details of the document owner. Any supporting comments would also be helpful. If you reply 'No' or 'Not Applicable' to any question, please explain why, within the context of your organization, the requirement or control is not required and not implemented. Clarification If you need clarification on any questions, please select 'Clarification required' from the dropdown box and ask for clarification next to the blue highlighted question number in the Clarification worksheet. (Rows in the Clarification worksheet are highlighted automatically when you select 'Clarification required' in the ISO27k Gap Analysis Questions worksheet). Summary of Responses The 'Summary of Responses' tab provides a breakdown of your responses to the gap analysis questionnaire. Gap analysis report Once all responses and evidence have been reviewed and any clarification questions have been answered and accepted, a consolidated gap analysis report will be provided. This report will highlight any identified gaps. It will also make recommendations for improvement as part of the ISO/IEC 27001:2022 certification process. Further details about are provided in the body of the Gap Analysis report. [This gap analysis questionnaire was generously donated to the ISO27k Toolkit by Marty Carter.]
B11: This work is copyright © 2024, Marty Carter and ISO27k Forum, some rights reserved. It is licensed under the Creative Commons Attribution-Noncommercial-Sharealike 4.0 International License. You are welcome to reproduce, circulate, use and create derivative works from this provided that (a) it is not sold or incorporated into a commercial product, (b) it is properly attributed to the ISO27k Forum (www.ISO27001security.com), and (c) if shared, derivative works are shared under the same terms as this.

Sheet Summary of Responses
B2: ISO/IEC 27001:2022 Gap analysis questionnaire - Summary of responses - Falcon Freight Solutions
B4: This table summarises the responses across the two parts of the gap analysis, and is provided as a guide only.
D6: Yes | E6: No | F6: Not Applicable | G6: Refer to comments | H6: Clarification required
B7: ISO/IEC 27001:2022 Clauses (28 questions) | D7: =COUNTIF('ISO27k Gap Analysis Questions'!I10:I43, "1") -> 0 | E7: =COUNTIF('ISO27k Gap Analysis Questions'!J10:J43, "1") -> 22 | F7: =COUNTIF('ISO27k Gap Analysis Questions'!K10:K43, "1") -> 0 | G7: =COUNTIF('ISO27k Gap Analysis Questions'!L10:L43, "1") -> 6 | H7: =COUNTIF('ISO27k Gap Analysis Questions'!M10:M43, "1") -> 0
B8: ISO/IEC 27001:2022 Annex A Controls (133 questions)
B9: Domain 5 - Organizational Controls (66 questions) | D9: =COUNTIF('ISO27k Gap Analysis Questions'!I46:I111, "1") -> 2 | E9: =COUNTIF('ISO27k Gap Analysis Questions'!J46:J111, "1") -> 51 | F9: =COUNTIF('ISO27k Gap Analysis Questions'!K46:K111, "1") -> 0 | G9: =COUNTIF('ISO27k Gap Analysis Questions'!L46:L111, "1") -> 13 | H9: =COUNTIF('ISO27k Gap Analysis Questions'!M46:M111, "1") -> 0
B10: Domain 6 - People Controls (15 questions) | D10: =COUNTIF('ISO27k Gap Analysis Questions'!I113:I127, "1") -> 5 | E10: =COUNTIF('ISO27k Gap Analysis Questions'!J113:J127, "1") -> 6 | F10: =COUNTIF('ISO27k Gap Analysis Questions'!K113:K127, "1") -> 0 | G10: =COUNTIF('ISO27k Gap Analysis Questions'!L113:L127, "1") -> 4 | H10: =COUNTIF('ISO27k Gap Analysis Questions'!M113:M127, "1") -> 0
B11: Domain 7 - Physical Controls (14 questions) | D11: =COUNTIF('ISO27k Gap Analysis Questions'!I129:I142, "1") -> 7 | E11: =COUNTIF('ISO27k Gap Analysis Questions'!J129:J142, "1") -> 3 | F11: =COUNTIF('ISO27k Gap Analysis Questions'!K129:K142, "1") -> 0 | G11: =COUNTIF('ISO27k Gap Analysis Questions'!L129:L142, "1") -> 4 | H11: =COUNTIF('ISO27k Gap Analysis Questions'!M129:M142, "1") -> 0
B12: Domain 8 - Technological Controls (38 questions) | D12: =COUNTIF('ISO27k Gap Analysis Questions'!I144:I181, "1") -> 2 | E12: =COUNTIF('ISO27k Gap Analysis Questions'!J144:J181, "1") -> 18 | F12: =COUNTIF('ISO27k Gap Analysis Questions'!K144:K181, "1") -> 9 | G12: =COUNTIF('ISO27k Gap Analysis Questions'!L144:L181, "1") -> 9 | H12: =COUNTIF('ISO27k Gap Analysis Questions'!M144:M181, "1") -> 0
C14: Total number of clarification questions asked
B15: This box below serves as a simple check for how many questions require clarification from the table above against how many questions were actually asked in the Clarification worksheet. The two totals should match.
B17: ISO/IEC 27001:2022 Clauses (28 questions) | D17: =COUNTIF(Clarification!F6:F39, "1") -> 0 | E17: =IF(AND(H7>0,D17<H7),"You have requested clarification on ISO/IEC 27001 Clause questions but have not yet entered them all in the Clarification worksheet.","")
B18: ISO/IEC 27001:2022 Annex A security controls (133 questions)
B19: Domain 5 - Organizational Controls (66 questions) | D19: =COUNTIF(Clarification!F42:F107, "1") -> 0 | E19: =IF(AND(H9>0,D19<H9),"You have requested clarification on ISO/IEC 27001 Organizational Control questions but have not yet entered them all in the Clarification worksheet.","")
B20: Domain 6 - People Controls (15 questions) | D20: =COUNTIF(Clarification!F109:F123, "1") -> 0 | E20: =IF(AND(H10>0,D20<H10),"You have requested clarification on ISO/IEC 27001 People Control questions but have not yet entered them all in the Clarification worksheet.","")
B21: Domain 7 - Physical Controls (14 questions) | D21: =COUNTIF(Clarification!F125:F138, "1") -> 0 | E21: =IF(AND(H11>0,D21<H11),"You have requested clarification on ISO/IEC 27001 Physical Control questions but have not yet entered them all in the Clarification worksheet.","")
B22: Domain 8 - Technological Controls (38 questions) | D22: =COUNTIF(Clarification!F140:F177, "1") -> 0 | E22: =IF(AND(H12>0,D22<H12),"You have requested clarification on ISO/IEC 27001 Technological Control questions but have not yet entered them all in the Clarification worksheet.","")
E24: The cells above contain formulae and should not be deleted.

Sheet ISO27k Gap Analysis Questions
B1: ISO/IEC 27001:2022 Information Security Management System (ISMS) GAP ANALYSIS QUESTIONNAIRE Falcon Freight Solutions
B3: ="There are "&COUNT(A10:A43)&" ISO/IEC 27001:2022 Clauses questions, plus "&COUNT(A46:A181)&" ISO/IEC 27001:2022 Annex A questions across the 4 security control domains. So far, you've answered "&COUNTIF(I10:I43,"1")&" ISO/IEC 27001:2022 Clause questions as Yes, "&COUNTIF(J10:J43,"1")&" as No, "&COUNTIF(K10:K43,"1")&" as Not Applicable, referred "&COUNTIF(L10:L43,"1")&" question(s) to comments, and asked for clarification on "&COUNTIF(M10:M43,"1")&" question(s). So far, you've answered "&COUNTIF(I46:I181,"1")&" ISO/IEC 27001:2022 Annex A questions as Yes, "&COUNTIF(J46:J181,"1")&" as No, "&COUNTIF(K46:K181,"1")&" as Not Applicable, referred "&COUNTIF(L46:L181,"1")&" question(s) to comments, and asked for clarification on "&COUNTIF(M46:M181,"1")&" question(s)." -> There are 28 ISO/IEC 27001:2022 Clauses questions, plus 133 ISO/IEC 27001:2022 Annex A questions across the 4 security control domains. So far, you've answered 0 ISO/IEC 27001:2022 Clause questions as Yes, 22 as No, 0 as Not Applicable, referred 6 question(s) to comments, and asked for clarification on 0 question(s). So far, you've answered 16 ISO/IEC 27001:2022 Annex A questions as Yes, 78 as No, 9 as Not Applicable, referred 30 question(s) to comments, and asked for clarification on 0 question(s).
B5: ISO/IEC 27001:2022 Clauses gap analysis questionnaire | D5: ISO/IEC 27001:2022 Annex A security controls gap analysis questionnaire
B7: Ref | C7: Question | D7: Response | E7: Policy | F7: Other document | G7: Document reference | H7: Comments | I7: These columns can be hidden
B8: ISO/IEC 27001:2022 Clauses gap analysis questionnaire
B9: Clause 4 - Context of the Organization | D9: Select your response from the dropdown box. | E9: Enter the details of the Policy related to this requirement (if applicable) | F9: Enter the details of the any other document related to this requirement (if applicable) | G9: Enter the document(s) reference details or a link to the document | H9: Add comments or enter a customised response here. | I9: Yes | J9: No | K9: NA | L9: Refer to comments | M9: Clarification required
A10: 1 | B10: 4.1a | C10: Has the organization determined external and internal issues that are relevant to and affect the ISMS' ability to achieve its intended outcomes? | D10: No | H10: External/internal issues (regional regulatory landscape, competitor and vendor dependencies) are discussed informally at leadership meetings but not formally documented as ISMS context. | I10: =IF($D10="Yes", 1, "") | J10: =IF($D10="No", 1, "") -> 1 | K10: =IF($D10="Not Applicable", 1, "") | L10: =IF($D10="Refer to comments", 1, "") | M10: =IF($D10="Clarification required", 1, "")
A11: 1 | B11: 4.2a | C11: Has the organization identified interested parties relevant to the ISMS, their relevant requirements and which of these will be addressed by the ISMS? | D11: No | H11: Interested parties (customers, customs authorities, freight partners, regulators) are not formally identified or mapped against ISMS requirements. | I11: =IF($D11="Yes", 1, "") | J11: =IF($D11="No", 1, "") -> 1 | K11: =IF($D11="Not Applicable", 1, "") | L11: =IF($D11="Refer to comments", 1, "") | M11: =IF($D11="Clarification required", 1, "")
A12: 1 | B12: 4.3a | C12: Has the organization determined the scope of its ISMS? | D12: No | H12: No ISMS scope has been defined; Falcon Freight has not yet formalized which sites, systems or business units would be in scope. | I12: =IF($D12="Yes", 1, "") | J12: =IF($D12="No", 1, "") -> 1 | K12: =IF($D12="Not Applicable", 1, "") | L12: =IF($D12="Refer to comments", 1, "") | M12: =IF($D12="Clarification required", 1, "")
A13: 1 | B13: 4.4a | C13: Has the organization established, implemented, maintained, and continually improves an ISMS in accordance with the requirements of ISO/IEC 27001:2022? | D13: No | H13: No ISMS has been established; information security is currently managed on an ad hoc basis by the IT team. | I13: =IF($D13="Yes", 1, "") | J13: =IF($D13="No", 1, "") -> 1 | K13: =IF($D13="Not Applicable", 1, "") | L13: =IF($D13="Refer to comments", 1, "") | M13: =IF($D13="Clarification required", 1, "")
B14: Clause 5 - Leadership | D14: Select your response from the dropdown box. | E14: Enter the details of the Policy related to this requirement (if applicable) | F14: Enter the details of the any other document related to this requirement (if applicable) | G14: Enter the document(s) reference details or a link to the document | H14: Add comments or enter a customised response here. | I14: Yes | J14: No | K14: NA | L14: Refer to comments | M14: Clarification required
A15: 1 | B15: 5.1a | C15: Are the objectives of the ISMS compatible with the organization's strategic direction and mission? | D15: Refer to comments | H15: Management supports growth and client trust generally, but no documented ISMS objectives exist to compare against strategic direction. | I15: =IF($D15="Yes", 1, "") | J15: =IF($D15="No", 1, "") | K15: =IF($D15="Not Applicable", 1, "") | L15: =IF($D15="Refer to comments", 1, "") -> 1 | M15: =IF($D15="Clarification required", 1, "")
A16: 1 | B16: 5.2a | C16: Is an Information Security Policy available and appropriate to the purpose and context of the organization and does it support the strategic direction of the company? | D16: No | H16: No formal Information Security Policy exists; IT operates from informal practices rather than an approved policy document. | I16: =IF($D16="Yes", 1, "") | J16: =IF($D16="No", 1, "") -> 1 | K16: =IF($D16="Not Applicable", 1, "") | L16: =IF($D16="Refer to comments", 1, "") | M16: =IF($D16="Clarification required", 1, "")
A17: 1 | B17: 5.3a | C17: Has the organization's top management established (and are they supportive of,) a mechanism for communicating responsibilities and authorities for roles relevant to information security within the organization? | D17: Refer to comments | H17: Responsibilities are communicated verbally by the IT Manager and Operations leads across regional offices, but no formal RACI or communication mechanism is documented. | I17: =IF($D17="Yes", 1, "") | J17: =IF($D17="No", 1, "") | K17: =IF($D17="Not Applicable", 1, "") | L17: =IF($D17="Refer to comments", 1, "") -> 1 | M17: =IF($D17="Clarification required", 1, "")
B18: Clause 6 - Planning | D18: Select your response from the dropdown box. | E18: Enter the details of the Policy related to this requirement (if applicable) | F18: Enter the details of the any other document related to this requirement (if applicable) | G18: Enter the document(s) reference details or a link to the document | H18: Add comments or enter a customised response here. | I18: Yes | J18: No | K18: NA | L18: Refer to comments | M18: Clarification required
A19: 1 | B19: 6.1a | C19: Has organization defined and applied an information security risk assessment process? | D19: No | H19: No formal information security risk assessment methodology has been defined or applied across the organization. | I19: =IF($D19="Yes", 1, "") | J19: =IF($D19="No", 1, "") -> 1 | K19: =IF($D19="Not Applicable", 1, "") | L19: =IF($D19="Refer to comments", 1, "") | M19: =IF($D19="Clarification required", 1, "")
A20: 1 | B20: 6.1b | C20: Does the organization have a documented risk treatment process? | D20: No | H20: No documented risk treatment process exists; risks are addressed reactively when incidents occur. | I20: =IF($D20="Yes", 1, "") | J20: =IF($D20="No", 1, "") -> 1 | K20: =IF($D20="Not Applicable", 1, "") | L20: =IF($D20="Refer to comments", 1, "") | M20: =IF($D20="Clarification required", 1, "")
A21: 1 | B21: 6.1c | C21: Has the organization produced a Statement of Applicability (SoA)? | D21: No | H21: No Statement of Applicability has been produced. | I21: =IF($D21="Yes", 1, "") | J21: =IF($D21="No", 1, "") -> 1 | K21: =IF($D21="Not Applicable", 1, "") | L21: =IF($D21="Refer to comments", 1, "") | M21: =IF($D21="Clarification required", 1, "")
A22: 1 | B22: 6.2a | C22: Has the organization established information security objectives at applicable functions and levels within the business and are they consistent with the Information Security Policy? | D22: No | H22: No information security objectives have been set at a functional or departmental level. | I22: =IF($D22="Yes", 1, "") | J22: =IF($D22="No", 1, "") -> 1 | K22: =IF($D22="Not Applicable", 1, "") | L22: =IF($D22="Refer to comments", 1, "") | M22: =IF($D22="Clarification required", 1, "")
A23: 1 | B23: 6.3a | C23: When the organization determines the need for changes to the information security management system, are the changes carried out in a planned manner? | D23: Refer to comments | H23: Changes to IT systems (e.g. the shipment tracking platform) go through basic IT change control, but this is not linked to a formal ISMS change process. | I23: =IF($D23="Yes", 1, "") | J23: =IF($D23="No", 1, "") | K23: =IF($D23="Not Applicable", 1, "") | L23: =IF($D23="Refer to comments", 1, "") -> 1 | M23: =IF($D23="Clarification required", 1, "")
B24: Clause 7 - Support | D24: Select your response from the dropdown box. | E24: Enter the details of the Policy related to this requirement (if applicable) | F24: Enter the details of the any other document related to this requirement (if applicable) | G24: Enter the document(s) reference details or a link to the document | H24: Add comments or enter a customised response here. | I24: Yes | J24: No | K24: NA | L24: Refer to comments | M24: Clarification required
A25: 1 | B25: 7.1a | C25: Has the organization determined and does it provide the resources needed for the establishment, implementation, maintenance, and continual improvement of the ISMS? | D25: Refer to comments | H25: The IT department is resourced for day-to-day operations, but no dedicated budget or resourcing has been allocated for ISMS establishment. | I25: =IF($D25="Yes", 1, "") | J25: =IF($D25="No", 1, "") | K25: =IF($D25="Not Applicable", 1, "") | L25: =IF($D25="Refer to comments", 1, "") -> 1 | M25: =IF($D25="Clarification required", 1, "")
A26: 1 | B26: 7.2a | C26: Has the organization determined the necessary competence of person(s) doing work under its control that affects its information security performance? | D26: No | H26: Competence requirements for information-security-relevant roles have not been formally defined. | I26: =IF($D26="Yes", 1, "") | J26: =IF($D26="No", 1, "") -> 1 | K26: =IF($D26="Not Applicable", 1, "") | L26: =IF($D26="Refer to comments", 1, "") | M26: =IF($D26="Clarification required", 1, "")
A27: 1 | B27: 7.3a | C27: Are the organizations employees made aware of the Information Security Policy? | D27: No | H27: Employees are not made aware of an Information Security Policy, as none currently exists. | I27: =IF($D27="Yes", 1, "") | J27: =IF($D27="No", 1, "") -> 1 | K27: =IF($D27="Not Applicable", 1, "") | L27: =IF($D27="Refer to comments", 1, "") | M27: =IF($D27="Clarification required", 1, "")
A28: 1 | B28: 7.4a | C28: Has the organization determined the need for internal and external communications relevant to the ISMS? | D28: Refer to comments | H28: Internal/external communications happen through normal business channels (email, regional office calls) but have not been assessed against ISMS communication needs. | I28: =IF($D28="Yes", 1, "") | J28: =IF($D28="No", 1, "") | K28: =IF($D28="Not Applicable", 1, "") | L28: =IF($D28="Refer to comments", 1, "") -> 1 | M28: =IF($D28="Clarification required", 1, "")
A29: 1 | B29: 7.5a | C29: Does the organization's ISMS include documented information as required by ISO/IEC 27001:2022? | D29: No | H29: No ISMS documented information (policies, procedures, records) is currently maintained. | I29: =IF($D29="Yes", 1, "") | J29: =IF($D29="No", 1, "") -> 1 | K29: =IF($D29="Not Applicable", 1, "") | L29: =IF($D29="Refer to comments", 1, "") | M29: =IF($D29="Clarification required", 1, "")
A30: 1 | B30: 7.5b | C30: Is documented information required by the ISMS and ISO/IEC 27001:2022 controlled? | D30: No | H30: No document control process exists for information-security-related documentation. | I30: =IF($D30="Yes", 1, "") | J30: =IF($D30="No", 1, "") -> 1 | K30: =IF($D30="Not Applicable", 1, "") | L30: =IF($D30="Refer to comments", 1, "") | M30: =IF($D30="Clarification required", 1, "")
B31: Clause 8 - Operation | D31: Select your response from the dropdown box. | E31: Enter the details of the Policy related to this requirement (if applicable) | F31: Enter the details of the any other document related to this requirement (if applicable) | G31: Enter the document(s) reference details or a link to the document | H31: Add comments or enter a customised response here. | I31: Yes | J31: No | K31: NA | L31: Refer to comments | M31: Clarification required
A32: 1 | B32: 8.1a | C32: Has the organization planned, implemented and does it control the processes needed to meet requirements, and to implement the actions determined in Clause 6 (Planning)? | D32: No | H32: No formal operational planning tied to Clause 6 risk treatment exists, since risk treatment itself is not yet formalized. | I32: =IF($D32="Yes", 1, "") | J32: =IF($D32="No", 1, "") -> 1 | K32: =IF($D32="Not Applicable", 1, "") | L32: =IF($D32="Refer to comments", 1, "") | M32: =IF($D32="Clarification required", 1, "")
A33: 1 | B33: 8.2a | C33: Does the organization perform information security risk assessments at planned intervals or when significant changes are proposed or occur? | D33: No | H33: Risk assessments are not performed at planned intervals; reviews only occur reactively after an incident or client audit request. | I33: =IF($D33="Yes", 1, "") | J33: =IF($D33="No", 1, "") -> 1 | K33: =IF($D33="Not Applicable", 1, "") | L33: =IF($D33="Refer to comments", 1, "") | M33: =IF($D33="Clarification required", 1, "")
A34: 1 | B34: 8.3a | C34: Has the organization implemented an information security risk treatment plan? | D34: No | H34: No risk treatment plan has been implemented. | I34: =IF($D34="Yes", 1, "") | J34: =IF($D34="No", 1, "") -> 1 | K34: =IF($D34="Not Applicable", 1, "") | L34: =IF($D34="Refer to comments", 1, "") | M34: =IF($D34="Clarification required", 1, "")
B35: Clause 9 - Performance evaluation | D35: Select your response from the dropdown box. | E35: Enter the details of the Policy related to this requirement (if applicable) | F35: Enter the details of the any other document related to this requirement (if applicable) | G35: Enter the document(s) reference details or a link to the document | H35: Add comments or enter a customised response here. | I35: Yes | J35: No | K35: NA | L35: Refer to comments | M35: Clarification required
A36: 1 | B36: 9.1a | C36: Has the organization determined what needs to monitored and measured, including information security processes and controls? | D36: No | H36: Monitoring is currently limited to basic IT system uptime/performance; no information security monitoring and measurement plan exists. | I36: =IF($D36="Yes", 1, "") | J36: =IF($D36="No", 1, "") -> 1 | K36: =IF($D36="Not Applicable", 1, "") | L36: =IF($D36="Refer to comments", 1, "") | M36: =IF($D36="Clarification required", 1, "")
A37: 1 | B37: 9.2a | C37: Does the organization conduct internal audits of their ISMS at planned intervals? | D37: No | H37: No internal ISMS audit programme exists. | I37: =IF($D37="Yes", 1, "") | J37: =IF($D37="No", 1, "") -> 1 | K37: =IF($D37="Not Applicable", 1, "") | L37: =IF($D37="Refer to comments", 1, "") | M37: =IF($D37="Clarification required", 1, "")
A38: 1 | B38: 9.2b | C38: Has the organization planned, established, implemented and does it maintain an audit programme(s), including the frequency, methods, responsibilities, planning requirements and reporting? | D38: No | H38: No audit programme has been established. | I38: =IF($D38="Yes", 1, "") | J38: =IF($D38="No", 1, "") -> 1 | K38: =IF($D38="Not Applicable", 1, "") | L38: =IF($D38="Refer to comments", 1, "") | M38: =IF($D38="Clarification required", 1, "")
A39: 1 | B39: 9.3a | C39: Does the organizations top management review the organization's ISMS at planned intervals to ensure its continuing suitability, adequacy and effectiveness? | D39: No | H39: Top management does not currently perform structured ISMS management reviews. | I39: =IF($D39="Yes", 1, "") | J39: =IF($D39="No", 1, "") -> 1 | K39: =IF($D39="Not Applicable", 1, "") | L39: =IF($D39="Refer to comments", 1, "") | M39: =IF($D39="Clarification required", 1, "")
A40: 1 | B40: 9.3b | C40: Do the results of management reviews include decisions related to continual improvement opportunities and any needs for changes to the ISMS? | D40: No | H40: As no management review process exists, there are no formal continual improvement decisions being tracked. | I40: =IF($D40="Yes", 1, "") | J40: =IF($D40="No", 1, "") -> 1 | K40: =IF($D40="Not Applicable", 1, "") | L40: =IF($D40="Refer to comments", 1, "") | M40: =IF($D40="Clarification required", 1, "")
B41: Clause 10 - Improvement | D41: Select your response from the dropdown box. | E41: Enter the details of the Policy related to this requirement (if applicable) | F41: Enter the details of the any other document related to this requirement (if applicable) | G41: Enter the document(s) reference details or a link to the document | H41: Add comments or enter a customised response here. | I41: Yes | J41: No | K41: NA | L41: Refer to comments | M41: Clarification required
A42: 1 | B42: 10.1a | C42: Does the organization continually improve the suitability, adequacy, and effectiveness of their ISMS? | D42: No | H42: There is no structured continual improvement process for information security; improvements happen informally when gaps are noticed. | I42: =IF($D42="Yes", 1, "") | J42: =IF($D42="No", 1, "") -> 1 | K42: =IF($D42="Not Applicable", 1, "") | L42: =IF($D42="Refer to comments", 1, "") | M42: =IF($D42="Clarification required", 1, "")
A43: 1 | B43: 10.2a | C43: When a nonconformity occurs, does the organization react to the nonconformity, and as applicable take action to control and correct it? | D43: Refer to comments | H43: Operational nonconformities (e.g. shipment/data handling errors) are corrected on a case-by-case basis but not through a documented ISMS nonconformity process. | I43: =IF($D43="Yes", 1, "") | J43: =IF($D43="No", 1, "") | K43: =IF($D43="Not Applicable", 1, "") | L43: =IF($D43="Refer to comments", 1, "") -> 1 | M43: =IF($D43="Clarification required", 1, "")
...

Sheet Clarification
B1: ISO/IEC 27001:2022 Information Security Management System (ISMS) GAP ANALYSIS QUESTIONNAIRE - Clarification required Falcon Freight Solutions
B3: Ref | C3: Question | D3: Clarification question | E3: Response
B4: ISO/IEC 27001:2022 Clauses Gap Analysis Questionnaire - Clarification | E4: Question numbers highlighted in blue indicate that clarification is required and a clarification question needs to be asked.
B5: Clause 4 - Context of the Organization | F5: Hidden
A6: 1 | B6: 4.1a | C6: Has the organization determined external and internal issues that are relevant to and affect the ISMS' ability to achieve its intended outcomes? | F6: =COUNTIF(D6, "*") -> 0 | G6: =COUNTIF('ISO27k Gap Analysis Questions'!M10, "1") -> 0
A7: 1 | B7: 4.2a | C7: Has the organization identified interested parties relevant to the ISMS, their relevant requirements and which of these will be addressed by the ISMS? | F7: =COUNTIF(D7, "*") -> 0 | G7: =COUNTIF('ISO27k Gap Analysis Questions'!M11, "1") -> 0
A8: 1 | B8: 4.3a | C8: Has the organization determined the scope of its ISMS? | F8: =COUNTIF(D8, "*") -> 0 | G8: =COUNTIF('ISO27k Gap Analysis Questions'!M12, "1") -> 0
A9: 1 | B9: 4.4a | C9: Has the organization established, implemented, maintained, and continually improves an ISMS in accordance with the requirements of ISO/IEC 27001:2022? | F9: =COUNTIF(D9, "*") -> 0 | G9: =COUNTIF('ISO27k Gap Analysis Questions'!M13, "1") -> 0
B10: Clause 5 - Leadership
A11: 1 | B11: 5.1a | C11: Are the objectives of the ISMS compatible with the organization's strategic direction and mission? | F11: =COUNTIF(D11, "*") -> 0 | G11: =COUNTIF('ISO27k Gap Analysis Questions'!M15, "1") -> 0
A12: 1 | B12: 5.2a | C12: Is an Information Security Policy available and appropriate to the purpose and context of the organization and does it support the strategic direction of the company? | F12: =COUNTIF(D12, "*") -> 0 | G12: =COUNTIF('ISO27k Gap Analysis Questions'!M16, "1") -> 0
A13: 1 | B13: 5.3a | C13: Has the organization's top management established (and are they supportive of,) a mechanism for communicating responsibilities and authorities for roles relevant to information security within the organization? | F13: =COUNTIF(D13, "*") -> 0 | G13: =COUNTIF('ISO27k Gap Analysis Questions'!M17, "1") -> 0
B14: Clause 6 - Planning
A15: 1 | B15: 6.1a | C15: Has organization defined and applied an information security risk assessment process? | F15: =COUNTIF(D15, "*") -> 0 | G15: =COUNTIF('ISO27k Gap Analysis Questions'!M19, "1") -> 0
A16: 1 | B16: 6.1b | C16: Does the organization have a documented risk treatment process? | F16: =COUNTIF(D16, "*") -> 0 | G16: =COUNTIF('ISO27k Gap Analysis Questions'!M20, "1") -> 0
A17: 1 | B17: 6.1c | C17: Has the organization produced a Statement of Applicability (SoA)? | F17: =COUNTIF(D17, "*") -> 0 | G17: =COUNTIF('ISO27k Gap Analysis Questions'!M21, "1") -> 0
A18: 1 | B18: 6.2a | C18: Has the organization established information security objectives at applicable functions and levels within the business and are they consistent with the Information Security Policy? | F18: =COUNTIF(D18, "*") -> 0 | G18: =COUNTIF('ISO27k Gap Analysis Questions'!M22, "1") -> 0
A19: 1 | B19: 6.3a | C19: When the organization determines the need for changes to the information security management system, are the changes carried out in a planned manner? | F19: =COUNTIF(D19, "*") -> 0 | G19: =COUNTIF('ISO27k Gap Analysis Questions'!M23, "1") -> 0
B20: Clause 7 - Support
A21: 1 | B21: 7.1a | C21: Has the organization determined and does it provide the resources needed for the establishment, implementation, maintenance, and continual improvement of the ISMS? | F21: =COUNTIF(D21, "*") -> 0 | G21: =COUNTIF('ISO27k Gap Analysis Questions'!M25, "1") -> 0
A22: 1 | B22: 7.2a | C22: Has the organization determined the necessary competence of person(s) doing work under its control that affects its information security performance? | F22: =COUNTIF(D22, "*") -> 0 | G22: =COUNTIF('ISO27k Gap Analysis Questions'!M26, "1") -> 0
A23: 1 | B23: 7.3a | C23: Are the organizations employees made aware of the Information Security Policy? | F23: =COUNTIF(D23, "*") -> 0 | G23: =COUNTIF('ISO27k Gap Analysis Questions'!M27, "1") -> 0
A24: 1 | B24: 7.4a | C24: Has the organization determined the need for internal and external communications relevant to the ISMS? | F24: =COUNTIF(D24, "*") -> 0 | G24: =COUNTIF('ISO27k Gap Analysis Questions'!M28, "1") -> 0
A25: 1 | B25: 7.5a | C25: Does the organization's ISMS include documented information as required by ISO/IEC 27001:2022? | F25: =COUNTIF(D25, "*") -> 0 | G25: =COUNTIF('ISO27k Gap Analysis Questions'!M29, "1") -> 0
A26: 1 | B26: 7.5b | C26: Is documented information required by the ISMS and by ISO/IEC 27001:2022 controlled? | F26: =COUNTIF(D26, "*") -> 0 | G26: =COUNTIF('ISO27k Gap Analysis Questions'!M30, "1") -> 0
B27: Clause 8 - Operation
A28: 1 | B28: 8.1a | C28: Has the organization planned, implemented and does it control the processes needed to meet requirements, and to implement the actions determined in Clause 6 (Planning)? | F28: =COUNTIF(D28, "*") -> 0 | G28: =COUNTIF('ISO27k Gap Analysis Questions'!M32, "1") -> 0
A29: 1 | B29: 8.2a | C29: Does the organization perform information security risk assessments at planned intervals or when significant changes are proposed or occur? | F29: =COUNTIF(D29, "*") -> 0 | G29: =COUNTIF('ISO27k Gap Analysis Questions'!M33, "1") -> 0
A30: 1 | B30: 8.3a | C30: Has the organization implemented an information security risk treatment plan? | F30: =COUNTIF(D30, "*") -> 0 | G30: =COUNTIF('ISO27k Gap Analysis Questions'!M34, "1") -> 0
B31: Clause 9 - Performance evaluation
A32: 1 | B32: 9.1a | C32: Has the organization determined what needs to monitored and measured, including information security processes and controls? | F32: =COUNTIF(D32, "*") -> 0 | G32: =COUNTIF('ISO27k Gap Analysis Questions'!M36, "1") -> 0
A33: 1 | B33: 9.2a | C33: Does the organization conduct internal audits of their ISMS at planned intervals? | F33: =COUNTIF(D33, "*") -> 0 | G33: =COUNTIF('ISO27k Gap Analysis Questions'!M37, "1") -> 0
A34: 1 | B34: 9.2b | C34: Has the organization planned, established, implemented and does it maintain an audit programme(s), including the frequency, methods, responsibilities, planning requirements and reporting? | F34: =COUNTIF(D34, "*") -> 0 | G34: =COUNTIF('ISO27k Gap Analysis Questions'!M38, "1") -> 0
A35: 1 | B35: 9.3a | C35: Does the organizations top management review the organization's ISMS at planned intervals to ensure its continuing suitability, adequacy and effectiveness? | F35: =COUNTIF(D35, "*") -> 0 | G35: =COUNTIF('ISO27k Gap Analysis Questions'!M39, "1") -> 0
A36: 1 | B36: 9.3b | C36: Do the results of management reviews include decisions related to continual improvement opportunities and any needs for changes to the ISMS? | F36: =COUNTIF(D36, "*") -> 0 | G36: =COUNTIF('ISO27k Gap Analysis Questions'!M40, "1") -> 0
B37: Clause 10 - Improvement
A38: 1 | B38: 10.1a | C38: Does the organization continually improve the suitability, adequacy, and effectiveness of their ISMS? | F38: =COUNTIF(D38, "*") -> 0 | G38: =COUNTIF('ISO27k Gap Analysis Questions'!M42, "1") -> 0
A39: 1 | B39: 10.2a | C39: When a nonconformity occurs, does the organization react to the nonconformity, and as applicable take action to control and correct it? | F39: =COUNTIF(D39, "*") -> 0 | G39: =COUNTIF('ISO27k Gap Analysis Questions'!M43, "1") -> 0
B40: ISO/IEC 27001:2022 Annex A Gap Analysis Questionnaire - Clarification
B41: 5 - ORGANIZATIONAL CONTROLS
...
